Workbook

Sheet 시트2
A1: final_project_WBS_업무관리
A2: 노란 칸(담당·실제 시작일·실제 완료일·비고)만 입력합니다. 예정일은 시작일과 시작·완료 D로 자동 계산됩니다. 담당은 한 명만 적습니다. 작업명이 진한 노랑인 행은 기간 단축 위험 구간입니다.
A3: 프로젝트 시작일 (D1) | C3: 46322 | F3: ※ 시작일 2026-10-27(화) = D1. 토·일 제외, 공휴일 미반영(기간 내 공휴일 없음). 일정·담당은 Final_Project_파일_관리_대장의 담당자(정·부)·생성일자 기준.
A4: 오늘 기준일 (지연일 계산용) | C4: 46324 | F4: ※ 오늘 기준일 = TODAY() 자동. 신호: 초록=지연 없음, 노랑=1일 지연, 빨강=2일 이상 지연, 완료=실제 완료일 입력됨.
Q5: 기존 항목이 바뀐 위치 (합쳐짐·나뉨·이동)
A6: WBS Level | B6: 작업명 | C6: 담당 | D6: 시작 D | E6: 완료 D | F6: 예정 시작일 | G6: 예정 완료일 | H6: 예정 소요일 | I6: 실제 시작일 | J6: 실제 완료일 | K6: 지연일 | L6: 신호 | M6: 문서 산출물 | N6: 비고 | O6: 구현 산출물 | Q6: 기존 항목 (v1) | R6: 변경 | S6: 지금 위치
A7: 0 | B7: 프로젝트 관리 (상시) | D7: 1 | E7: 24 | F7: 10-27 (화) | G7: 11-27 (금) | H7: 24 | K7: 0 | L7: 초록 | Q7: 2.4 구현작업 (모두) | R7: 삭제 | S7: 주차별 화면 구현·API 구현·단위 테스트 행으로 나눔
A8: 0.1 | B8: 파일 관리 대장 관리 | C8: 지웅 | D8: 1 | E8: 24 | F8: 46322 | G8: 46353 | H8: 24 | K8: 0 | L8: 초록 | Q8: 2.4.1 DB 구축 | R8: 합침 | S8: 1.12 개발 환경 구축
A9: 0.2 | B9: 회의록 작성·관리 | C9: 진희 | D9: 1 | E9: 24 | F9: 46322 | G9: 46353 | H9: 24 | K9: 0 | L9: 초록 | Q9: 2.4.2 백엔드 API 구현 | R9: 나눔 | S9: 2.3 백엔드 API 구현 ①, 3.2 백엔드 API 구현 ②
A10: 0.3 | B10: WBS 진행 점검 | C10: 지웅 | D10: 1 | E10: 24 | F10: 46322 | G10: 46353 | H10: 24 | K10: 0 | L10: 초록 | Q10: 2.4.3 화면 구현 | R10: 나눔 | S10: 2.2 화면 구현 ①, 3.1 화면 구현 ②, 4.2 리포트 화면
A11: 1주차 | B11: 기획·설계 문서 및 개발 환경 구축 | D11: 1 | E11: 4 | F11: 10-27 (화) | G11: 10-30 (금) | H11: 4 | K11: 0 | L11: 초록 | Q11: 2.4.4 AI 기능 연동 | R11: 나눔 | S11: 2.4 AI 기능 연동 ①, 3.3 AI 기능 연동 ②, 4.1 리포트 생성
A12: 1.1 | B12: 서비스 플로우차트 작성 | C12: 혜현 | D12: 1 | E12: 1 | F12: 46322 | G12: 46322 | H12: 1 | I12: 46322 | J12: 46322 | K12: 0 | L12: 완료 | Q12: 2.4.5 관리자 기능 구현 | R12: 합침 | S12: 3.1 화면 구현 ②, 3.2 백엔드 API 구현 ②
A13: 1.2 | B13: WBS 업무관리 작성 | C13: 지웅 | D13: 1 | E13: 2 | F13: 46322 | G13: 46323 | H13: 2 | I13: 46322 | J13: 46323 | K13: 1 | L13: 노랑 | Q13: 2.4.6 통합 및 동작 확인 | R13: 합침 | S13: 4.8 통합 테스트
A14: 1.3 | B14: PRD 정의서 작성 | C14: 소현 | D14: 1 | E14: 2 | F14: 46322 | G14: 46323 | H14: 2 | I14: 46322 | J14: 46323 | K14: 1 | L14: 노랑 | Q14: 2.1 AI 아키텍처 작성 | R14: 합침 | S14: 2.4.1 AI 아키텍처 작성 및 Qwen3 PoC
A15: 1.4 | B15: 화면정의서 작성 | C15: 진희 | D15: 1 | E15: 4 | F15: 46322 | G15: 46325 | H15: 4 | I15: 46323 | J15: 46323 | K15: 0 | L15: 초록 | Q15: 2.2 테스트 계획서 작성 | R15: 이동 | S15: 2.1
A16: 1.5 | B16: TRD 정의서 작성 | C16: 성준 | D16: 2 | E16: 4 | F16: 46323 | G16: 46325 | H16: 3 | I16: 46323 | J16: 46325 | K16: 0 | L16: 초록 | Q16: 2.3 테스트 케이스 작성 | R16: 이동 | S16: 2.5
A17: 1.6 | B17: 기능정의서 작성 | C17: 지웅 | D17: 2 | E17: 4 | F17: 46323 | G17: 46325 | H17: 3 | I17: 46323 | J17: 46324 | K17: 0 | L17: 초록 | Q17: 3.1 / 3.3 / 3.5 1~3차 QA | R17: 합침 | S17: 단위 테스트 ①②③ (2.6, 3.4, 4.5)
A18: 1.7 | B18: 시나리오 기획서 작성 | C18: 혜현 | D18: 2 | E18: 4 | F18: 46323 | G18: 46325 | H18: 3 | I18: 46323 | J18: 46324 | K18: 0 | L18: 초록 | Q18: 3.2 / 3.4 버그수정·재테스트 | R18: 합침 | S18: 단위 테스트 ①②③에 포함 (항목명 삭제)
A19: 1.8 | B19: 기술 아키텍처 작성 | C19: 진희 | D19: 3 | E19: 4 | F19: 46324 | G19: 46325 | H19: 2 | I19: 46324 | J19: 46324 | K19: 0 | L19: 초록 | Q19: 4.1 통합 테스트 | R19: 이동 | S19: 4.8
A20: 1.9 | B20: ERD 작성 | C20: 성준 | D20: 3 | E20: 4 | F20: 46324 | G20: 46332 | H20: 2 | I20: 46324 | J20: 46324 | K20: 0 | L20: 초록 | N20: ERD, 테이블 정의서 통합 | Q20: 4.2 결함 조치 및 성능 개선 | R20: 합침 | S20: 결함 조치는 단위·통합 테스트에 포함, 성능 개선은 4.4
A21: 1.1 | B21: 테이블 정의서 작성 | C21: 진희 | D21: 3 | E21: 4 | F21: 46324 | G21: 46332 | H21: 2 | I21: 46324 | J21: 46324 | K21: 0 | L21: 초록 | Q21: 4.3 관리자 매뉴얼 작성 | R21: 이동 | S21: 4.6
A22: 1.11 | B22: API 명세서 작성 | C22: 혜현 | D22: 3 | E22: 4 | F22: 46324 | G22: 46332 | H22: 2 | I22: 46324 | J22: 46324 | K22: 0 | L22: 초록 | N22: 1주차 안에 완료 | Q22: 4.4 사용자 매뉴얼 작성 | R22: 이동 | S22: 4.7
A23: 1.12 | B23: 개발 환경 구축 (Docker Compose·AI 런타임·DB 구축·메모리 사양·설명서) | C23: 팀원 | D23: 3 | E23: 4 | F23: 46324 | G23: 46325 | H23: 2 | I23: 46324 | K23: 0 | L23: 초록 | Q23: 4.5 산출물 최종 정리 | R23: 합침 | S23: 5.1 결과보고서 작성 및 산출물 최종 정리
A24: 2주차 | B24: 기능 개발 ① — 로그인·공고·지원·AI 기반 + 단위 테스트 | D24: 5 | E24: 9 | F24: 11-02 (월) | G24: 11-06 (금) | H24: 5 | K24: 0 | L24: 초록 | Q24: 5.1~5.4 | R24: 유지 | S24: 5.1~5.4 (5.1에 산출물 정리 합침)
A25: 2.1 | B25: 테스트 계획서 작성 | C25: 지웅 | D25: 5 | E25: 6 | F25: 46328 | G25: 46332 | H25: 2 | K25: 0 | L25: 초록 | N25: 2주차로 이동
A26: 2.2 | B26: 화면 구현 ① (로그인·공고·개인정보 동의·이력서 제출·마이페이지) | C26: 팀원 | D26: 5 | E26: 8 | F26: 46328 | G26: 46331 | H26: 4 | K26: 0 | L26: 초록
A27: 2.3 | B27: 백엔드 API 구현 ① (로그인·공고·지원·이력서·질문 은행) | C27: 팀원 | D27: 5 | E27: 8 | F27: 46328 | G27: 46331 | H27: 4 | K27: 0 | L27: 초록
A28: 2.4 | B28: AI 기능 연동 ① — 모델·음성·이력서 | D28: 5 | E28: 9 | F28: 46328 | G28: 46332 | H28: 5 | K28: 0 | L28: 초록
A29: 2.4.1 | B29: AI 아키텍처 작성 | C29: 성준 | D29: 5 | E29: 7 | F29: 46328 | G29: 46332 | H29: 3 | K29: 0 | L29: 초록
A30: 2.4.2 | B30: STT 연동 및 정확도 측정 (WER 10% 미만) | C30: 팀원 | D30: 5 | E30: 7 | F30: 46328 | G30: 46330 | H30: 3 | K30: 0 | L30: 초록
A31: 2.4.3 | B31: 이력서 PDF 추출 (PyMuPDF + Qwen3) | C31: 팀원 | D31: 8 | E31: 9 | F31: 46331 | G31: 46332 | H31: 2 | K31: 0 | L31: 초록
A32: 2.4.4 | B32: TTS 연동 (실패 시 텍스트 표시) | C32: 팀원 | D32: 8 | E32: 9 | F32: 46331 | G32: 46332 | H32: 2 | K32: 0 | L32: 초록
A33: 2.5 | B33: 테스트 케이스 작성 | C33: 성준 | D33: 6 | E33: 8 | F33: 46329 | G33: 46343 | H33: 3 | K33: 0 | L33: 초록 | N33: 2주차로 이동
A34: 2.6 | B34: 단위 테스트 ① (로그인·공고·지원·이력서·음성) | C34: 팀원 | D34: 9 | E34: 9 | F34: 46332 | G34: 46332 | H34: 1 | K34: 0 | L34: 초록
A35: 3주차 | B35: 기능 개발 ② — 면접 진행·관리자·AI 평가 + 단위 테스트 | D35: 10 | E35: 14 | F35: 11-09 (월) | G35: 11-13 (금) | H35: 5 | K35: 0 | L35: 초록 | N35: 2주차와 이어짐
A36: 3.1 | B36: 화면 구현 ② (면접 진행·관리자 공고 관리·지원자 관리) | C36: 팀원 | D36: 10 | E36: 14 | F36: 46335 | G36: 46339 | H36: 5 | K36: 0 | L36: 초록
A37: 3.2 | B37: 백엔드 API 구현 ② (면접 진행·관리자 공고 관리·지원자 관리·합격 결정) | C37: 팀원 | D37: 10 | E37: 14 | F37: 46335 | G37: 46339 | H37: 5 | K37: 0 | L37: 초록 | N37: 관리자 기능은 백엔드와 함께
A38: 3.3 | B38: AI 기능 연동 ② — 면접 흐름·꼬리질문·분석·채점 | D38: 10 | E38: 15 | F38: 46335 | G38: 46342 | H38: 6 | K38: 0 | L38: 초록
A39: 3.3.1 | B39: 면접 흐름 엔진 (LangGraph) | C39: 팀원 | D39: 10 | E39: 11 | F39: 46335 | G39: 46336 | H39: 2 | K39: 0 | L39: 초록 | N39: ⚠ 기간 단축 위험.
A40: 3.3.2 | B40: 전달력·답변 품질 분석 및 AI 오류 처리 | C40: 팀원 | D40: 10 | E40: 14 | F40: 46335 | G40: 46339 | H40: 5 | K40: 0 | L40: 초록 | N40: 판정 기준값 보정 포함
...

Sheet 시트1
A1: final_project_WBS_업무관리 | F1: 진행중 | H1: 초과 기한 | J1: 완료 | L1: 조기마감
A2: 작업 | B2: 담당 | C2: 진행율 | D2: 1주차 | I2: 2주차 | N2: 3주차 | S2: 4주차 | X2: 5주차
D3: 서류작업완료 | I3: 구현 - 세세한 부분 조정 | N3: 테스트 | S3: 서류작업 | X3: 마무리작업
E4: 46322 | F4: 46323 | G4: 46324 | H4: 46325 | I4: 46328 | J4: 46329 | K4: 46330 | L4: 46331 | M4: 46332 | N4: 46335 | O4: 46336 | P4: 46337 | Q4: 46338 | R4: 46339 | S4: 46342 | T4: 46343 | U4: 46344 | V4: 46345 | W4: 46346 | X4: 46349 | Y4: 46350 | Z4: 46351 | AA4: 46352 | AB4: 46353
A5: ='시트2'!B8 -> 파일 관리 대장 관리 | B5: ='시트2'!C8 -> 지웅 | C5: =IF('시트2'!$L8="완료","완료","") | E5: =IF('시트2'!$F8="",0,IF(AND('시트2'!$F8<=E$4,'시트2'!$G8>=E$4),1,0)) -> 1 | F5: =IF('시트2'!$F8="",0,IF(AND('시트2'!$F8<=F$4,'시트2'!$G8>=F$4),1,0)) -> 1 | G5: =IF('시트2'!$F8="",0,IF(AND('시트2'!$F8<=G$4,'시트2'!$G8>=G$4),1,0)) -> 1 | H5: =IF('시트2'!$F8="",0,IF(AND('시트2'!$F8<=H$4,'시트2'!$G8>=H$4),1,0)) -> 1 | I5: =IF('시트2'!$F8="",0,IF(AND('시트2'!$F8<=I$4,'시트2'!$G8>=I$4),1,0)) -> 1 | J5: =IF('시트2'!$F8="",0,IF(AND('시트2'!$F8<=J$4,'시트2'!$G8>=J$4),1,0)) -> 1 | K5: =IF('시트2'!$F8="",0,IF(AND('시트2'!$F8<=K$4,'시트2'!$G8>=K$4),1,0)) -> 1 | L5: =IF('시트2'!$F8="",0,IF(AND('시트2'!$F8<=L$4,'시트2'!$G8>=L$4),1,0)) -> 1 | ... AB5: =IF('시트2'!$F8="",0,IF(AND('시트2'!$F8<=AB$4,'시트2'!$G8>=AB$4),1,0)) -> 1
A6: ='시트2'!B9 -> 회의록 작성·관리 | B6: ='시트2'!C9 -> 진희 | C6: =IF('시트2'!$L9="완료","완료","") | E6: =IF('시트2'!$F9="",0,IF(AND('시트2'!$F9<=E$4,'시트2'!$G9>=E$4),1,0)) -> 1 | F6: =IF('시트2'!$F9="",0,IF(AND('시트2'!$F9<=F$4,'시트2'!$G9>=F$4),1,0)) -> 1 | G6: =IF('시트2'!$F9="",0,IF(AND('시트2'!$F9<=G$4,'시트2'!$G9>=G$4),1,0)) -> 1 | H6: =IF('시트2'!$F9="",0,IF(AND('시트2'!$F9<=H$4,'시트2'!$G9>=H$4),1,0)) -> 1 | I6: =IF('시트2'!$F9="",0,IF(AND('시트2'!$F9<=I$4,'시트2'!$G9>=I$4),1,0)) -> 1 | J6: =IF('시트2'!$F9="",0,IF(AND('시트2'!$F9<=J$4,'시트2'!$G9>=J$4),1,0)) -> 1 | K6: =IF('시트2'!$F9="",0,IF(AND('시트2'!$F9<=K$4,'시트2'!$G9>=K$4),1,0)) -> 1 | L6: =IF('시트2'!$F9="",0,IF(AND('시트2'!$F9<=L$4,'시트2'!$G9>=L$4),1,0)) -> 1 | ... AB6: =IF('시트2'!$F9="",0,IF(AND('시트2'!$F9<=AB$4,'시트2'!$G9>=AB$4),1,0)) -> 1
A7: ='시트2'!B10 -> WBS 진행 점검 | B7: ='시트2'!C10 -> 지웅 | C7: =IF('시트2'!$L10="완료","완료","") | E7: =IF('시트2'!$F10="",0,IF(AND('시트2'!$F10<=E$4,'시트2'!$G10>=E$4),1,0)) -> 1 | F7: =IF('시트2'!$F10="",0,IF(AND('시트2'!$F10<=F$4,'시트2'!$G10>=F$4),1,0)) -> 1 | G7: =IF('시트2'!$F10="",0,IF(AND('시트2'!$F10<=G$4,'시트2'!$G10>=G$4),1,0)) -> 1 | H7: =IF('시트2'!$F10="",0,IF(AND('시트2'!$F10<=H$4,'시트2'!$G10>=H$4),1,0)) -> 1 | I7: =IF('시트2'!$F10="",0,IF(AND('시트2'!$F10<=I$4,'시트2'!$G10>=I$4),1,0)) -> 1 | J7: =IF('시트2'!$F10="",0,IF(AND('시트2'!$F10<=J$4,'시트2'!$G10>=J$4),1,0)) -> 1 | K7: =IF('시트2'!$F10="",0,IF(AND('시트2'!$F10<=K$4,'시트2'!$G10>=K$4),1,0)) -> 1 | L7: =IF('시트2'!$F10="",0,IF(AND('시트2'!$F10<=L$4,'시트2'!$G10>=L$4),1,0)) -> 1 | ... AB7: =IF('시트2'!$F10="",0,IF(AND('시트2'!$F10<=AB$4,'시트2'!$G10>=AB$4),1,0)) -> 1
A8: ='시트2'!B11 -> 기획·설계 문서 및 개발 환경 구축 | B8: ='시트2'!C11 | C8: =IF('시트2'!$L11="완료","완료","") | E8: =IF('시트2'!$F11="",0,IF(AND('시트2'!$F11<=E$4,'시트2'!$G11>=E$4),1,0)) -> 0 | F8: =IF('시트2'!$F11="",0,IF(AND('시트2'!$F11<=F$4,'시트2'!$G11>=F$4),1,0)) -> 0 | G8: =IF('시트2'!$F11="",0,IF(AND('시트2'!$F11<=G$4,'시트2'!$G11>=G$4),1,0)) -> 0 | H8: =IF('시트2'!$F11="",0,IF(AND('시트2'!$F11<=H$4,'시트2'!$G11>=H$4),1,0)) -> 0 | I8: =IF('시트2'!$F11="",0,IF(AND('시트2'!$F11<=I$4,'시트2'!$G11>=I$4),1,0)) -> 0 | J8: =IF('시트2'!$F11="",0,IF(AND('시트2'!$F11<=J$4,'시트2'!$G11>=J$4),1,0)) -> 0 | K8: =IF('시트2'!$F11="",0,IF(AND('시트2'!$F11<=K$4,'시트2'!$G11>=K$4),1,0)) -> 0 | L8: =IF('시트2'!$F11="",0,IF(AND('시트2'!$F11<=L$4,'시트2'!$G11>=L$4),1,0)) -> 0 | ... AB8: =IF('시트2'!$F11="",0,IF(AND('시트2'!$F11<=AB$4,'시트2'!$G11>=AB$4),1,0)) -> 0
A9: ='시트2'!B12 -> 서비스 플로우차트 작성 | B9: ='시트2'!C12 -> 혜현 | C9: =IF('시트2'!$L12="완료","완료","") -> 완료 | E9: =IF('시트2'!$F12="",0,IF(AND('시트2'!$F12<=E$4,'시트2'!$G12>=E$4),1,0)) -> 1 | F9: =IF('시트2'!$F12="",0,IF(AND('시트2'!$F12<=F$4,'시트2'!$G12>=F$4),1,0)) -> 0 | G9: =IF('시트2'!$F12="",0,IF(AND('시트2'!$F12<=G$4,'시트2'!$G12>=G$4),1,0)) -> 0 | H9: =IF('시트2'!$F12="",0,IF(AND('시트2'!$F12<=H$4,'시트2'!$G12>=H$4),1,0)) -> 0 | I9: =IF('시트2'!$F12="",0,IF(AND('시트2'!$F12<=I$4,'시트2'!$G12>=I$4),1,0)) -> 0 | J9: =IF('시트2'!$F12="",0,IF(AND('시트2'!$F12<=J$4,'시트2'!$G12>=J$4),1,0)) -> 0 | K9: =IF('시트2'!$F12="",0,IF(AND('시트2'!$F12<=K$4,'시트2'!$G12>=K$4),1,0)) -> 0 | L9: =IF('시트2'!$F12="",0,IF(AND('시트2'!$F12<=L$4,'시트2'!$G12>=L$4),1,0)) -> 0 | ... AB9: =IF('시트2'!$F12="",0,IF(AND('시트2'!$F12<=AB$4,'시트2'!$G12>=AB$4),1,0)) -> 0
A10: ='시트2'!B13 -> WBS 업무관리 작성 | B10: ='시트2'!C13 -> 지웅 | C10: =IF('시트2'!$L13="완료","완료","") | E10: =IF('시트2'!$F13="",0,IF(AND('시트2'!$F13<=E$4,'시트2'!$G13>=E$4),1,0)) -> 1 | F10: =IF('시트2'!$F13="",0,IF(AND('시트2'!$F13<=F$4,'시트2'!$G13>=F$4),1,0)) -> 1 | G10: =IF('시트2'!$F13="",0,IF(AND('시트2'!$F13<=G$4,'시트2'!$G13>=G$4),1,0)) -> 0 | H10: =IF('시트2'!$F13="",0,IF(AND('시트2'!$F13<=H$4,'시트2'!$G13>=H$4),1,0)) -> 0 | I10: =IF('시트2'!$F13="",0,IF(AND('시트2'!$F13<=I$4,'시트2'!$G13>=I$4),1,0)) -> 0 | J10: =IF('시트2'!$F13="",0,IF(AND('시트2'!$F13<=J$4,'시트2'!$G13>=J$4),1,0)) -> 0 | K10: =IF('시트2'!$F13="",0,IF(AND('시트2'!$F13<=K$4,'시트2'!$G13>=K$4),1,0)) -> 0 | L10: =IF('시트2'!$F13="",0,IF(AND('시트2'!$F13<=L$4,'시트2'!$G13>=L$4),1,0)) -> 0 | ... AB10: =IF('시트2'!$F13="",0,IF(AND('시트2'!$F13<=AB$4,'시트2'!$G13>=AB$4),1,0)) -> 0
A11: ='시트2'!B14 -> PRD 정의서 작성 | B11: ='시트2'!C14 -> 소현 | C11: =IF('시트2'!$L14="완료","완료","") | E11: =IF('시트2'!$F14="",0,IF(AND('시트2'!$F14<=E$4,'시트2'!$G14>=E$4),1,0)) -> 1 | F11: =IF('시트2'!$F14="",0,IF(AND('시트2'!$F14<=F$4,'시트2'!$G14>=F$4),1,0)) -> 1 | G11: =IF('시트2'!$F14="",0,IF(AND('시트2'!$F14<=G$4,'시트2'!$G14>=G$4),1,0)) -> 0 | H11: =IF('시트2'!$F14="",0,IF(AND('시트2'!$F14<=H$4,'시트2'!$G14>=H$4),1,0)) -> 0 | I11: =IF('시트2'!$F14="",0,IF(AND('시트2'!$F14<=I$4,'시트2'!$G14>=I$4),1,0)) -> 0 | J11: =IF('시트2'!$F14="",0,IF(AND('시트2'!$F14<=J$4,'시트2'!$G14>=J$4),1,0)) -> 0 | K11: =IF('시트2'!$F14="",0,IF(AND('시트2'!$F14<=K$4,'시트2'!$G14>=K$4),1,0)) -> 0 | L11: =IF('시트2'!$F14="",0,IF(AND('시트2'!$F14<=L$4,'시트2'!$G14>=L$4),1,0)) -> 0 | ... AB11: =IF('시트2'!$F14="",0,IF(AND('시트2'!$F14<=AB$4,'시트2'!$G14>=AB$4),1,0)) -> 0
A12: ='시트2'!B15 -> 화면정의서 작성 | B12: ='시트2'!C15 -> 진희 | C12: =IF('시트2'!$L15="완료","완료","") | E12: =IF('시트2'!$F15="",0,IF(AND('시트2'!$F15<=E$4,'시트2'!$G15>=E$4),1,0)) -> 1 | F12: =IF('시트2'!$F15="",0,IF(AND('시트2'!$F15<=F$4,'시트2'!$G15>=F$4),1,0)) -> 1 | G12: =IF('시트2'!$F15="",0,IF(AND('시트2'!$F15<=G$4,'시트2'!$G15>=G$4),1,0)) -> 1 | H12: =IF('시트2'!$F15="",0,IF(AND('시트2'!$F15<=H$4,'시트2'!$G15>=H$4),1,0)) -> 1 | I12: =IF('시트2'!$F15="",0,IF(AND('시트2'!$F15<=I$4,'시트2'!$G15>=I$4),1,0)) -> 0 | J12: =IF('시트2'!$F15="",0,IF(AND('시트2'!$F15<=J$4,'시트2'!$G15>=J$4),1,0)) -> 0 | K12: =IF('시트2'!$F15="",0,IF(AND('시트2'!$F15<=K$4,'시트2'!$G15>=K$4),1,0)) -> 0 | L12: =IF('시트2'!$F15="",0,IF(AND('시트2'!$F15<=L$4,'시트2'!$G15>=L$4),1,0)) -> 0 | ... AB12: =IF('시트2'!$F15="",0,IF(AND('시트2'!$F15<=AB$4,'시트2'!$G15>=AB$4),1,0)) -> 0
A13: ='시트2'!B16 -> TRD 정의서 작성 | B13: ='시트2'!C16 -> 성준 | C13: =IF('시트2'!$L16="완료","완료","") | E13: =IF('시트2'!$F16="",0,IF(AND('시트2'!$F16<=E$4,'시트2'!$G16>=E$4),1,0)) -> 0 | F13: =IF('시트2'!$F16="",0,IF(AND('시트2'!$F16<=F$4,'시트2'!$G16>=F$4),1,0)) -> 1 | G13: =IF('시트2'!$F16="",0,IF(AND('시트2'!$F16<=G$4,'시트2'!$G16>=G$4),1,0)) -> 1 | H13: =IF('시트2'!$F16="",0,IF(AND('시트2'!$F16<=H$4,'시트2'!$G16>=H$4),1,0)) -> 1 | I13: =IF('시트2'!$F16="",0,IF(AND('시트2'!$F16<=I$4,'시트2'!$G16>=I$4),1,0)) -> 0 | J13: =IF('시트2'!$F16="",0,IF(AND('시트2'!$F16<=J$4,'시트2'!$G16>=J$4),1,0)) -> 0 | K13: =IF('시트2'!$F16="",0,IF(AND('시트2'!$F16<=K$4,'시트2'!$G16>=K$4),1,0)) -> 0 | L13: =IF('시트2'!$F16="",0,IF(AND('시트2'!$F16<=L$4,'시트2'!$G16>=L$4),1,0)) -> 0 | ... AB13: =IF('시트2'!$F16="",0,IF(AND('시트2'!$F16<=AB$4,'시트2'!$G16>=AB$4),1,0)) -> 0
A14: ='시트2'!B17 -> 기능정의서 작성 | B14: ='시트2'!C17 -> 지웅 | C14: =IF('시트2'!$L17="완료","완료","") | E14: =IF('시트2'!$F17="",0,IF(AND('시트2'!$F17<=E$4,'시트2'!$G17>=E$4),1,0)) -> 0 | F14: =IF('시트2'!$F17="",0,IF(AND('시트2'!$F17<=F$4,'시트2'!$G17>=F$4),1,0)) -> 1 | G14: =IF('시트2'!$F17="",0,IF(AND('시트2'!$F17<=G$4,'시트2'!$G17>=G$4),1,0)) -> 1 | H14: =IF('시트2'!$F17="",0,IF(AND('시트2'!$F17<=H$4,'시트2'!$G17>=H$4),1,0)) -> 1 | I14: =IF('시트2'!$F17="",0,IF(AND('시트2'!$F17<=I$4,'시트2'!$G17>=I$4),1,0)) -> 0 | J14: =IF('시트2'!$F17="",0,IF(AND('시트2'!$F17<=J$4,'시트2'!$G17>=J$4),1,0)) -> 0 | K14: =IF('시트2'!$F17="",0,IF(AND('시트2'!$F17<=K$4,'시트2'!$G17>=K$4),1,0)) -> 0 | L14: =IF('시트2'!$F17="",0,IF(AND('시트2'!$F17<=L$4,'시트2'!$G17>=L$4),1,0)) -> 0 | ... AB14: =IF('시트2'!$F17="",0,IF(AND('시트2'!$F17<=AB$4,'시트2'!$G17>=AB$4),1,0)) -> 0
A15: ='시트2'!B18 -> 시나리오 기획서 작성 | B15: ='시트2'!C18 -> 혜현 | C15: =IF('시트2'!$L18="완료","완료","") | E15: =IF('시트2'!$F18="",0,IF(AND('시트2'!$F18<=E$4,'시트2'!$G18>=E$4),1,0)) -> 0 | F15: =IF('시트2'!$F18="",0,IF(AND('시트2'!$F18<=F$4,'시트2'!$G18>=F$4),1,0)) -> 1 | G15: =IF('시트2'!$F18="",0,IF(AND('시트2'!$F18<=G$4,'시트2'!$G18>=G$4),1,0)) -> 1 | H15: =IF('시트2'!$F18="",0,IF(AND('시트2'!$F18<=H$4,'시트2'!$G18>=H$4),1,0)) -> 1 | I15: =IF('시트2'!$F18="",0,IF(AND('시트2'!$F18<=I$4,'시트2'!$G18>=I$4),1,0)) -> 0 | J15: =IF('시트2'!$F18="",0,IF(AND('시트2'!$F18<=J$4,'시트2'!$G18>=J$4),1,0)) -> 0 | K15: =IF('시트2'!$F18="",0,IF(AND('시트2'!$F18<=K$4,'시트2'!$G18>=K$4),1,0)) -> 0 | L15: =IF('시트2'!$F18="",0,IF(AND('시트2'!$F18<=L$4,'시트2'!$G18>=L$4),1,0)) -> 0 | ... AB15: =IF('시트2'!$F18="",0,IF(AND('시트2'!$F18<=AB$4,'시트2'!$G18>=AB$4),1,0)) -> 0
A16: ='시트2'!B19 -> 기술 아키텍처 작성 | B16: ='시트2'!C19 -> 진희 | C16: =IF('시트2'!$L19="완료","완료","") | E16: =IF('시트2'!$F19="",0,IF(AND('시트2'!$F19<=E$4,'시트2'!$G19>=E$4),1,0)) -> 0 | F16: =IF('시트2'!$F19="",0,IF(AND('시트2'!$F19<=F$4,'시트2'!$G19>=F$4),1,0)) -> 0 | G16: =IF('시트2'!$F19="",0,IF(AND('시트2'!$F19<=G$4,'시트2'!$G19>=G$4),1,0)) -> 1 | H16: =IF('시트2'!$F19="",0,IF(AND('시트2'!$F19<=H$4,'시트2'!$G19>=H$4),1,0)) -> 1 | I16: =IF('시트2'!$F19="",0,IF(AND('시트2'!$F19<=I$4,'시트2'!$G19>=I$4),1,0)) -> 0 | J16: =IF('시트2'!$F19="",0,IF(AND('시트2'!$F19<=J$4,'시트2'!$G19>=J$4),1,0)) -> 0 | K16: =IF('시트2'!$F19="",0,IF(AND('시트2'!$F19<=K$4,'시트2'!$G19>=K$4),1,0)) -> 0 | L16: =IF('시트2'!$F19="",0,IF(AND('시트2'!$F19<=L$4,'시트2'!$G19>=L$4),1,0)) -> 0 | ... AB16: =IF('시트2'!$F19="",0,IF(AND('시트2'!$F19<=AB$4,'시트2'!$G19>=AB$4),1,0)) -> 0
... A157: ='시트2'!B160 | B157: ='시트2'!C160 | C157: =IF('시트2'!$L160="완료","완료","") | E157: =IF('시트2'!$F160="",0,IF(AND('시트2'!$F160<=E$4,'시트2'!$G160>=E$4),1,0)) -> 0 | F157: =IF('시트2'!$F160="",0,IF(AND('시트2'!$F160<=F$4,'시트2'!$G160>=F$4),1,0)) -> 0 | G157: =IF('시트2'!$F160="",0,IF(AND('시트2'!$F160<=G$4,'시트2'!$G160>=G$4),1,0)) -> 0 | H157: =IF('시트2'!$F160="",0,IF(AND('시트2'!$F160<=H$4,'시트2'!$G160>=H$4),1,0)) -> 0 | I157: =IF('시트2'!$F160="",0,IF(AND('시트2'!$F160<=I$4,'시트2'!$G160>=I$4),1,0)) -> 0 | J157: =IF('시트2'!$F160="",0,IF(AND('시트2'!$F160<=J$4,'시트2'!$G160>=J$4),1,0)) -> 0 | K157: =IF('시트2'!$F160="",0,IF(AND('시트2'!$F160<=K$4,'시트2'!$G160>=K$4),1,0)) -> 0 | L157: =IF('시트2'!$F160="",0,IF(AND('시트2'!$F160<=L$4,'시트2'!$G160>=L$4),1,0)) -> 0 | ... AB157: =IF('시트2'!$F160="",0,IF(AND('시트2'!$F160<=AB$4,'시트2'!$G160>=AB$4),1,0)) -> 0

Sheet 선생님 피드백
A1: 선생님 피드백 반영 내역 (2026-10-28)
A3: 구분 | B3: 선생님 피드백 | C3: WBS 반영
A4: 공통 | B4: 날짜 순서대로 시퀀스를 맞춘다 | C4: 주차 안에서 시작일 순으로 정렬
A5: 공통 | B5: 항목마다 전담자를 정한다 (공통 작업도) | C5: 기존 담당자는 그대로 유지. "모두"였던 작업과 새 작업에만 담당 1명 제안
A6: 공통 | B6: 세부적으로 잡되 여유 있게 가지 않는다 | C6: 작업 수는 38개 → 43개로 최소한만 늘림 (개발 환경·AI 세분화)
A7: 공통 | B7: 개발 환경 세팅을 먼저, 모델은 나중 | C7: 1.12 개발 환경 구축을 1주차(10/29~10/30)에 배치
A8: 공통 | B8: Docker Compose·메모리 사양·서버/도커 설명서 | C8: 1.12 한 행에 포함
A9: 2팀 | B9: 테스트 계획서·케이스를 2주차로, 실제 테스트까지 | C9: 2.1 테스트 계획서, 2.5 테스트 케이스를 2주차로. 주차마다 단위 테스트 행
A10: 2팀 | B10: 3주차에 테스트만 따로 하는 구조 금지 | C10: 기존 3주차 QA 삭제. 3주차도 기능 개발 + 단위 테스트
A11: 2팀 | B11: 2·3주차를 맞물리게, 기능 단위로 분할 | C11: 주차마다 화면 구현 → API 구현 → AI 연동 → 단위 테스트
A12: 2팀 | B12: AI 기능 연동 세분화 (3주차보다 크게) | C12: AI 기능 연동 ①② 8개 작업 + 4.1 리포트 생성
A13: 2팀 | B13: 관리자 기능은 백엔드와 같이 | C13: 3.1·3.2에 관리자 공고 관리·지원자 관리 포함
A14: 2팀 | B14: 화면 구현과 백엔드 순서 | C14: 화면 구현 → 백엔드 API 순서로 배치
... A19: 참고(1·3팀) | B19: 코딩 테스트는 선택, 위험 구간은 노란색 | C19: 4.3 코딩 테스트(선택), 위험 작업은 작업명 진한 노랑
